Workbook

Sheet TD MEMO
A3: Unidad de Compra | B3: Proyectos | C3: Monto
A4: Bienes y Servicios | B4: 238 | C4: 1932801598
A5: Activos Fijos | B5: 18 | C5: 4545805005
A6: Administración de Fondos | B6: 47 | C6: 216217147
A7: Bienestar | B7: 1 | C7: 156000000
A8: Compras Convenio GORE Region de Los Lagos | B8: 16 | C8: 1438588008
A9: Obras Civiles | B9: 14 | C9: 7264673295
A10: Proyectos de Arrastre | B10: 59 | C10: 6588447864
A11: Total general | B11: 393 | C11: 22142532917

Sheet TD (2)
A1: PAC | B1: TIPO PAC | C1: ID Proyecto | D1: Nombre Proyecto | E1: Nombre responsable | F1: Cargo responsable | G1: Suma de Monto Total Ítem Año 2026
A2: PC26 | B2: Activos Fijos | C2: 1057922-10-PC26 | D2: REPOSICION CESFAM CON SAR RAHUE ALTO, OSORNO | E2: Maria Elena Muñoz | F2: Jefa (S) Sub. Dpto. De Inversiones De Equipos Y Equipamiento | G2: 1578831000
A3: PC26 | B3: Activos Fijos | C3: 1057922-11-PC26 | D3: HABILITACION ANGIOGRAFO HOSPITAL BASE DE OSORNO | E3: Maria Elena Muñoz | F3: Jefa (S) Sub. Dpto. De Inversiones De Equipos Y Equipamiento | G3: 1969068000
A4: PC26 | B4: Activos Fijos | C4: 1057922-12-PC26 | D4: CONSTRUCCION COSAM RAHUE, COMUNA OSORNO | E4: Maria Elena Muñoz | F4: Jefa (S) Sub. Dpto. De Inversiones De Equipos Y Equipamiento | G4: 18632000
A5: PC26 | B5: Activos Fijos | C5: 1057922-13-PC26 | D5: SUBTÍTULO 29 SECTORIAL 2026 | E5: Maria Elena Muñoz | F5: Jefa (S) Sub. Dpto. De Inversiones De Equipos Y Equipamiento | G5: 280000000
A6: PC26 | B6: Activos Fijos | C6: 1057922-14-PC26 | D6: SUBTÍTULO 29 OPERACIONAL SSO 2026 | E6: Maria Elena Muñoz | F6: Jefa (S) Sub. Dpto. De Inversiones De Equipos Y Equipamiento | G6: 61000000
A7: PC26 | B7: Activos Fijos | C7: 1057922-15-PC26 | D7: Equipamiento Ergonómico - Sillas | E7: Venecia Recabarren | F7: Jefatura Unidad Prev. Riesgos | G7: 1000000
A8: PC26 | B8: Activos Fijos | C8: 1057922-16-PC26 | D8: Adquisición de micrófono y cámara para videoconferencias del Centro Comunitario Kümelen | E8: Luis Flores | F8: Coordinador | G8: 250000
A9: PC26 | B9: Activos Fijos | C9: 1057922-17-PC26 | D9: Adquisición de megáfonos y gabinetes para la comunicación en emergencias, gestión de riesgos y protección de equipos | E9: Yuvit Garcia-Chacur | F9: DIRECTORA | G9: 780000
A10: PC26 | B10: Activos Fijos | C10: 1057922-18-PC26 | D10: REPOSICION CECOSF EL ENCANTO, COMUNA DE PUYEHUE | E10: Maria Elena Muñoz | F10: Jefa (S) Sub. Dpto. De Inversiones De Equipos Y Equipamiento | G10: 6773000
A11: PC26 | B11: Activos Fijos | C11: 1057922-19-PC26 | D11: Adquisición de productos e insumos para el programa de control y eliminación de la Tuberculosis | E11: NMaria Paz Gomez | F11: Referente Programa De Tuberculosis | G11: 19000000
A12: PC26 | B12: Activos Fijos | C12: 1057922-20-PC26 | D12: Adquisición de herramientas | E12: Pedro Fritz | F12: Director | G12: 300000
A13: PC26 | B13: Activos Fijos | C13: 1057922-21-PC26 | D13: Adquisicion equipamiento Servidor NAS y almacenamiento extra para respaldo y seguridad de la información | E13: Alejandro Nuñez | F13: Encargado Gestión De Sistemas | G13: 16000000
... A394: PC26 | B394: Obras Civiles | C394: 1057976-9-PC26 | D394: Contratación de Visita a Obra 2026 de las Consultorías: Especialidades y Arquitectura Obra CESFAM Bahía Mansa | E394: Rodrigo Neira | F394: Itos | G394: 9814756

Sheet TD3
A3: ID Proyecto | B3: PAC | C3: Unidad de Compra | D3: Nombre Proyecto | E3: Nombre ítem | F3: Cantidad de Ítems | G3: Nombre responsable | H3: Fecha de Inicio Compra | I3: Cargo responsable | J3: Cantidad OC | K3: Meses envío OC | L3: Suma de Monto Total Ítem Año 2026
A4: 1057532-156-PC24 | B4: Arrastre | C4: Bienes y Servicios | D4: servicios de control de asistencia del servicio de salud osorno | E4: Servicio Control Asistencia | F4: 2 | G4: Bruno Ojeda Alvarez | H4: 45292 | I4: Jefe Depto. Tecnologías de la Información | J4: 36 | K4: 01-01-2024,01-02-2024,01-03-2024,01-04-2024,01-05-2024,01-06-2024,01-07-2024,01-08-2024,01-09-2024,01-10-2024,01-11-2024,01-12-2024,01-01-2025,01-02-2025,01-03-2025,01-04-2025,01-05-2025,01-06-2025,01-07-2025,01-08-2025,01-09-2025,01-10-2025,01-11-2025,01-12-2025,01-01-2026,01-02-2026,01-03-2026,01-04-2026,01-05-2026,01-06-2026,01-07-2026,01-08-2026,01-09-2026,01-10-2026,01-11-2026,01-12-2026 | L4: 30000000
A5: 1057532-162-PC25 | B5: Arrastre | C5: Bienes y Servicios | D5: Convenio - de Suministro para adquisición de medicamentos faltantes CENABAST para establecimientos dependientes del SSO. | E5: Medicamentos | F5: 1 | G5: ELEUTERIO ROMAN | H5: 45748 | I5: JEFE SUBDEPTO FARMACIA | J5: 24 | K5: 01-05-2025,01-06-2025,01-07-2025,01-08-2025,01-09-2025,01-10-2025,01-11-2025,01-12-2025,01-01-2026,01-02-2026,01-03-2026,01-04-2026,01-05-2026,01-06-2026,01-07-2026,01-08-2026,01-09-2026,01-10-2026,01-11-2026,01-12-2026,01-01-2027,01-02-2027,01-03-2027,01-04-2027 | L5: 75000000
A6: 1057532-163-PC24 | B6: Arrastre | C6: Bienes y Servicios | D6: Servicio gestión flota vehicular SSO | E6: Control Flota | F6: 2 | G6: Bruno Ojeda Alvarez | H6: 45200 | I6: Jefe Depto. | J6: 36 | K6: 01-01-2024,01-02-2024,01-03-2024,01-04-2024,01-05-2024,01-06-2024,01-07-2024,01-08-2024,01-09-2024,01-10-2024,01-11-2024,01-12-2024,01-01-2025,01-02-2025,01-03-2025,01-04-2025,01-05-2025,01-06-2025,01-07-2025,01-08-2025,01-09-2025,01-10-2025,01-11-2025,01-12-2025,01-01-2026,01-02-2026,01-03-2026,01-04-2026,01-05-2026,01-06-2026,01-07-2026,01-08-2026,01-09-2026,01-10-2026,01-11-2026,01-12-2026 | L6: 6711996
A7: 1057532-172-PC25 | B7: Arrastre | C7: Bienes y Servicios | D7: Convenio - CONVENIO SERVICIO DE ASEO POR 18 MESES, PARA LA DIRECCION DEL SSO Y ESTABLECIMIENTOS DEPENDIENTES DE LA RED ASISTENCIAL | E7: Aseo | F7: 1 | G7: Lorena Torres Castillo | H7: 45839 | I7: ENCARGADA (S) SECCIÓN DE ADMINISTRACIÓN DE CONTRATOS | J7: 18 | K7: 01-07-2025,01-08-2025,01-09-2025,01-10-2025,01-11-2025,01-12-2025,01-01-2026,01-02-2026,01-03-2026,01-04-2026,01-05-2026,01-06-2026,01-07-2026,01-08-2026,01-09-2026,01-10-2026,01-11-2026,01-12-2026 | L7: 144000000
A8: 1057532-173-PC25 | B8: Arrastre | C8: Bienes y Servicios | D8: Convenio - CONVENIO DE ADQUISICION DE KIT POINT OF CARE (POC) CON ARRIENDO DE EQUIPO PARA ANALISIS DE MUESTRAS, SSO | E8: Equipo | F8: 1 | G8: Sofia Reyes | H8: 45839 | I8: Encargada | J8: 12 | K8: 01-08-2025,01-09-2025,01-10-2025,01-11-2025,01-12-2025,01-01-2026,01-02-2026,01-03-2026,01-04-2026,01-05-2026,01-06-2026,01-07-2026 | L8: 40833335
A9: 1057532-193-PC25 | B9: Arrastre | C9: Bienes y Servicios | D9: Convenio - ARRIENDO 159 EQUIPOS PC AIO PARA APOYAR LOS PORCESOS CLINICOS Y ADMINISTRATIVOS | E9: Insumos | F9: 2 | G9: Alvaro Montecinos | H9: 45870 | I9: Jefe (S) Subdepto. Soporte TIC | J9: 1 | K9: 01-01-2026,01-02-2026,01-03-2026,01-04-2026,01-05-2026,01-06-2026,01-07-2026,01-08-2026,01-09-2026,01-10-2026,01-11-2026,01-12-2026,01-01-2027,01-02-2027,01-03-2027,01-04-2027,01-05-2027,01-06-2027,01-07-2027,01-08-2027,01-09-2027,01-10-2027,01-11-2027,01-12-2027,01-01-2028,01-02-2028,01-03-2028,01-04-2028,01-05-2028,01-06-2028,01-07-2028,01-08-2028 | L9: 74068560
A10: 1057532-193-PC25 | B10: Arrastre | C10: Bienes y Servicios | D10: Convenio - ARRIENDO 159 EQUIPOS PC AIO PARA APOYAR LOS PROCESOS CLINICOS Y ADMINISTRATIVOS | E10: Insumos | F10: 2 | G10: Alvaro Montecinos | H10: 45992 | I10: Jefe (S) Subdepto. Soporte TIC | J10: 32 | K10: 01-01-2026,01-02-2026,01-03-2026,01-04-2026,01-05-2026,01-06-2026,01-07-2026,01-08-2026,01-09-2026,01-10-2026,01-11-2026,01-12-2026,01-01-2027,01-02-2027,01-03-2027,01-04-2027,01-05-2027,01-06-2027,01-07-2027,01-08-2027,01-09-2027,01-10-2027,01-11-2027,01-12-2027,01-01-2028,01-02-2028,01-03-2028,01-04-2028,01-05-2028,01-06-2028,01-07-2028,01-08-2028 | L10: 37034280
A11: 1057532-195-PC25 | B11: Arrastre | C11: Bienes y Servicios | D11: Convenio - SERVICIO DE ASEO PARA LA DSSO (BASE SAMU, EDIFICIO PLAZA SUR Y EDIFICIO M. RODRIGUEZ) POR 18 MESES (DESDE 01 JULIO 2025) | E11: Aseo | F11: 2 | G11: Lorena Torres Castillo | H11: 45658 | I11: Encargada (S) Sección Administración de Contratos | J11: 18 | K11: 01-07-2025,01-08-2025,01-09-2025,01-10-2025,01-11-2025,01-12-2025,01-01-2026,01-02-2026,01-03-2026,01-04-2026,01-05-2026,01-06-2026,01-07-2026,01-08-2026,01-09-2026,01-10-2026,01-11-2026,01-12-2026 | L11: 70333380
A12: 1057532-196-PC25 | B12: Arrastre | C12: Bienes y Servicios | D12: Convenio - SERVICIO DE SOPORTE Y MANTENCION RPT VHF SSO (PERIODO DOS AÑOS) | E12: Mantenimiento | F12: 2 | G12: ESTEBAN ALARCON BOHLE | H12: 45658 | I12: TECNICO RADIOCOMUNICACIONES | J12: 24 | K12: 01-01-2025,01-02-2025,01-03-2025,01-04-2025,01-05-2025,01-06-2025,01-07-2025,01-08-2025,01-09-2025,01-10-2025,01-11-2025,01-12-2025,01-01-2026,01-02-2026,01-03-2026,01-04-2026,01-05-2026,01-06-2026,01-07-2026,01-08-2026,01-09-2026,01-10-2026,01-11-2026,01-12-2026 | L12: 6255504
A13: 1057532-1-PC24 | B13: Arrastre | C13: Bienes y Servicios | D13: Sistema control de flota vehicular del Servicio de Salud Osorno | E13: Sistema de control de flota | F13: 1 | G13: Felipe Salvo Barriga | H13: 45292 | I13: Enc. Sección Mant. de Vehículos | J13: 36 | K13: 01-01-2024,01-02-2024,01-03-2024,01-04-2024,01-05-2024,01-06-2024,01-07-2024,01-08-2024,01-09-2024,01-10-2024,01-11-2024,01-12-2024,01-01-2025,01-02-2025,01-03-2025,01-04-2025,01-05-2025,01-06-2025,01-07-2025,01-08-2025,01-09-2025,01-10-2025,01-11-2025,01-12-2025,01-01-2026,01-02-2026,01-03-2026,01-04-2026,01-05-2026,01-06-2026,01-07-2026,01-08-2026,01-09-2026,01-10-2026,01-11-2026,01-12-2026 | L13: 6712008
A14: 1057532-209-PC25 | B14: Arrastre | C14: Bienes y Servicios | D14: Convenio - ADQUISICION DE 3 CUPOS DE RESIDENCIA PROTEGIDA PARA EL SERVICIO DE SALUD OSORNO EN LA PROVINCIA DE CONCEPCIÓN | E14: Servicio Residencial | F14: 2 | G14: Angelo Palma | H14: 45658 | I14: Jefe (s) Subdepto. Gestión Clínica y Administrativa Red Temática de Salud Mental de Especialidad | J14: 24 | K14: 01-01-2025,01-02-2025,01-03-2025,01-04-2025,01-05-2025,01-06-2025,01-07-2025,01-08-2025,01-09-2025,01-10-2025,01-11-2025,01-12-2025,01-01-2026,01-02-2026,01-03-2026,01-04-2026,01-05-2026,01-06-2026,01-07-2026,01-08-2026,01-09-2026,01-10-2026,01-11-2026,01-12-2026 | L14: 48115128
A15: 1057532-210-PC25 | B15: Arrastre | C15: Bienes y Servicios | D15: Convenio - ADQUISICION DE 12 CUPOS DE RESIDENCIA PROTEGIDA PARA EL SERVICIO DE SALUD OSORNO EN LA CIUDAD DE OSORNO | E15: Servicio Residencial | F15: 2 | G15: Angelo Palma | H15: 45658 | I15: Jefe (s) Subdepto. Gestión Clínica y Administrativa Red Temática de Salud Mental de Especialidad | J15: 24 | K15: 01-01-2025,01-02-2025,01-03-2025,01-04-2025,01-05-2025,01-06-2025,01-07-2025,01-08-2025,01-09-2025,01-10-2025,01-11-2025,01-12-2025,01-01-2026,01-02-2026,01-03-2026,01-04-2026,01-05-2026,01-06-2026,01-07-2026,01-08-2026,01-09-2026,01-10-2026,01-11-2026,01-12-2026 | L15: 237155100
A16: 1057532-211-PC25 | B16: Arrastre | C16: Bienes y Servicios | D16: Convenio - ADQUISICION DE 10 CUPOS RESIDENCIA PROTEGIDA DE ALTA COMPLEJIDAD PARA EL SERVICIO DE SALUD OSORNO DE LA CIUDAD DE OSORNO | E16: Servicio Residencial | F16: 2 | G16: Angelo Palma | H16: 45658 | I16: Jefe (s) Subdepto. Gestión Clínica y Administrativa Red Temática de Salud Mental de Especialidad | J16: 24 | K16: 01-01-2025,01-02-2025,01-03-2025,01-04-2025,01-05-2025,01-06-2025,01-07-2025,01-08-2025,01-09-2025,01-10-2025,01-11-2025,01-12-2025,01-01-2026,01-02-2026,01-03-2026,01-04-2026,01-05-2026,01-06-2026,01-07-2026,01-08-2026,01-09-2026,01-10-2026,01-11-2026,01-12-2026 | L16: 284700000
A17: 1057532-281-PC26 | B17: PC26 | C17: Bienes y Servicios | D17: Mantención Plotter Canon IPF 770, del depto. de Proyectos. | E17: Mantencion | F17: 1 | G17: Mario Barrientos | H17: 46266 | I17: Jefe Subdepto. Diseño De Infraestructura De Salud | J17: 1 | K17: 46266 | L17: 1250000
A18: 1057532-282-PC26 | B18: PC26 | C18: Bienes y Servicios | D18: Compra rollos papel para impresión del Departamento de Proyectos SSO. | E18: Rollos | F18: 1 | G18: Mario Barrientos | H18: 46174 | I18: Jefe Subdepto. Diseño De Infraestructura De Salud | J18: 1 | K18: 46174 | L18: 300000
A19: 1057532-283-PC26 | B19: PC26 | C19: Bienes y Servicios | D19: Compra Tinta Plotter Canon IPF 770 | E19: Tinta Plotter | F19: 1 | G19: Mario Barrientos | H19: 46204 | I19: Jefe Subdepto. Diseño De Infraestructura De Salud | J19: 1 | K19: 46204 | L19: 1320000
A20: 1057532-284-PC26 | B20: PC26 | C20: Bienes y Servicios | D20: Adquisicición Hojas Prehospitalarias | E20: Talonarios | F20: 1 | G20: Silvia Delgado | H20: 46082 | I20: Encargada Proceso De Urgencia | J20: 1 | K20: 46082 | L20: 2000700
A21: 1057532-285-PC26 | B21: PC26 | C21: Bienes y Servicios | D21: Adquisicición Kit de Triage y Sistema de comando incidente | E21: Kit Sistema | F21: 1 | G21: Silvia Delgado | H21: 46082 | I21: Encargada Proceso De Urgencia | J21: 1 | K21: 46082 | L21: 1510005
A22: 1057532-286-PC26 | B22: PC26 | C22: Bienes y Servicios | D22: II Jornada de Capacitación Red de Urgencia | E22: Cafeteria | F22: 2 | G22: Silvia Delgado | H22: 46082 | I22: Encargada Proceso De Urgencia | J22: 1 | K22: 46082 | L22: 850000
A23: 1057532-286-PC26 | B23: PC26 | C23: Bienes y Servicios | D23: II Jornada de Capacitación Red de Urgencia | E23: Opalina | F23: 2 | G23: Silvia Delgado | H23: 46082 | I23: Encargada Proceso De Urgencia | J23: 1 | K23: 46082 | L23: 22500
A24: 1057532-287-PC26 | B24: PC26 | C24: Bienes y Servicios | D24: ?DIAGNÓSTICO Y DIALOGO PARTICIPATIVO COSAM RAHUE ?NOVIEMBRE 2026? | E24: Cafeteria | F24: 1 | G24: Camilo Martínez | H24: 46327 | I24: Director(S) | J24: 1 | K24: 46327 | L24: 540000
A25: 1057532-288-PC26 | B25: PC26 | C25: Bienes y Servicios | D25: Jornadas de encuentro y autocuidado Para usuarios y cuidadores ?SALUDABLE-MENTE en dispositivo COSAM RAHUE 2026 | E25: Alimentación | F25: 6 | G25: Camilo Martínez | H25: 46113 | I25: Director(S) | J25: 1 | K25: 46113 | L25: 135000
A26: 1057532-288-PC26 | B26: PC26 | C26: Bienes y Servicios | D26: Jornadas de encuentro y autocuidado Para usuarios y cuidadores ?SALUDABLE-MENTE en dispositivo COSAM RAHUE 2026 | E26: Alimentación | F26: 6 | G26: Camilo Martínez | H26: 46204 | I26: Director(S) | J26: 1 | K26: 46204 | L26: 135000
A27: 1057532-288-PC26 | B27: PC26 | C27: Bienes y Servicios | D27: Jornadas de encuentro y autocuidado Para usuarios y cuidadores ?SALUDABLE-MENTE en dispositivo COSAM RAHUE 2026 | E27: Alimentación | F27: 6 | G27: Camilo Martínez | H27: 46266 | I27: Director(S) | J27: 1 | K27: 46266 | L27: 135000
A28: 1057532-288-PC26 | B28: PC26 | C28: Bienes y Servicios | D28: Jornadas de encuentro y autocuidado Para usuarios y cuidadores ?SALUDABLE-MENTE en dispositivo COSAM RAHUE 2026 | E28: Alimentación | F28: 6 | G28: Camilo Martínez | H28: 46357 | I28: Director(S) | J28: 1 | K28: 46357 | L28: 135000
A29: 1057532-288-PC26 | B29: PC26 | C29: Bienes y Servicios | D29: Jornadas de encuentro y autocuidado Para usuarios y cuidadores ?SALUDABLE-MENTE en dispositivo COSAM RAHUE 2026 | E29: Cafeteria | F29: 6 | G29: Camilo Martínez | H29: 46113 | I29: Director(S) | J29: 1 | K29: 46113 | L29: 135000
A30: 1057532-288-PC26 | B30: PC26 | C30: Bienes y Servicios | D30: Jornadas de encuentro y autocuidado Para usuarios y cuidadores ?SALUDABLE-MENTE en dispositivo COSAM RAHUE 2026 | E30: Cafeteria | F30: 6 | G30: Camilo Martínez | H30: 46204 | I30: Director(S) | J30: 3 | K30: 01-07-2026,01-09-2026,01-12-2026 | L30: 405000
A31: 1057532-308-PC24 | B31: Arrastre | C31: Bienes y Servicios | D31: Convenio - 3 cupos Residencia Protegida para el Servicio de Salud Osorno en la Región Metropolitana | E31: Residencia | F31: 1 | G31: Antonia Caifil | H31: 45474 | I31: Jefa Subdepto. Gestión Clinica y Adm. | J31: 24 | K31: 01-01-2025,01-02-2025,01-03-2025,01-04-2025,01-05-2025,01-06-2025,01-07-2025,01-08-2025,01-09-2025,01-10-2025,01-11-2025,01-12-2025,01-01-2026,01-02-2026,01-03-2026,01-04-2026,01-05-2026,01-06-2026,01-07-2026,01-08-2026,01-09-2026,01-10-2026,01-11-2026,01-12-2026 | L31: 40432878
A32: 1057532-30-PC24 | B32: Arrastre | C32: Bienes y Servicios | D32: SISTEMAS DE COMUNICACIONES LTE WAVE PTX SERVICIO DE SALUD OSORNO | E32: Servicio | F32: 1 | G32: CATALINA VERA | H32: 45413 | I32: COORDINADORA EMERGENCIA | J32: 36 | K32: 01-06-2024,01-07-2024,01-08-2024,01-09-2024,01-10-2024,01-11-2024,01-12-2024,01-01-2025,01-02-2025,01-03-2025,01-04-2025,01-05-2025,01-06-2025,01-07-2025,01-08-2025,01-09-2025,01-10-2025,01-11-2025,01-12-2025,01-01-2026,01-02-2026,01-03-2026,01-04-2026,01-05-2026,01-06-2026,01-07-2026,01-08-2026,01-09-2026,01-10-2026,01-11-2026,01-12-2026,01-01-2027,01-02-2027,01-03-2027,01-04-2027,01-05-2024 | L32: 43333332
A33: 1057532-311-PC24 | B33: Arrastre | C33: Bienes y Servicios | D33: Convenio - ( cupos Hogar Protegido Varones para el Servicio de Salud Osorno en la ciudad de Osorno | E33: Residencia | F33: 1 | G33: Antonia Caifil | H33: 45444 | I33: Jefa Subdepto. Gestión Clínica y Adm. | J33: 24 | K33: 01-01-2025,01-02-2025,01-03-2025,01-04-2025,01-05-2025,01-06-2025,01-07-2025,01-08-2025,01-09-2025,01-10-2025,01-11-2025,01-12-2025,01-01-2026,01-02-2026,01-03-2026,01-04-2026,01-05-2026,01-06-2026,01-07-2026,01-08-2026,01-09-2026,01-10-2026,01-11-2026,01-12-2026 | L33: 78361124
A34: 1057532-315-PC24 | B34: Arrastre | C34: Bienes y Servicios | D34: Convenio - 08 Cupos Hogar Protegido Mujeres para el Servicio de Salud Osorno en la ciudad de Osorno | E34: Residencia | F34: 1 | G34: Antonia Caifil | H34: 45444 | I34: Jefa Subdepto. Gestión Clínica y Adm. | J34: 24 | K34: 01-01-2025,01-02-2025,01-03-2025,01-04-2025,01-05-2025,01-06-2025,01-07-2025,01-08-2025,01-09-2025,01-10-2025,01-11-2025,01-12-2025,01-01-2026,01-02-2026,01-03-2026,01-04-2026,01-05-2026,01-06-2026,01-07-2026,01-08-2026,01-09-2026,01-10-2026,01-11-2026,01-12-2026 | L34: 78361124
A35: 1057532-317-PC26 | B35: PC26 | C35: Bienes y Servicios | D35: ?Eco-huerto sustentable -Sistema de acuaponía sin suelo? COSAM RAHUE 2026 | E35: Macetero | F35: 1 | G35: Camilo Martínez | H35: 46082 | I35: Director(S) | J35: 1 | K35: 46082 | L35: 1500000
A36: 1057532-320-PC24 | B36: Arrastre | C36: Bienes y Servicios | D36: Convenio - SERVICIOS DE MANTENCIÓN, RECARGA E INSPECCION PREVENTIVA PARA RED HÚMEDA Y EXTINTORES EN ESTABLECIMIENTOS SSO | E36: Recarga | F36: 1 | G36: KARIN SCHOLZ | H36: 45444 | I36: Jefatura Dpto. de Calidad de Vida | J36: 30 | K36: 01-01-2025,01-02-2025,01-03-2025,01-04-2025,01-05-2025,01-06-2025,01-07-2025,01-08-2025,01-09-2025,01-10-2025,01-11-2025,01-12-2025,01-01-2026,01-02-2026,01-03-2026,01-04-2026,01-05-2026,01-06-2026,01-07-2026,01-08-2026,01-09-2026,01-10-2026,01-11-2026,01-12-2026,01-01-2027,01-02-2027,01-03-2027,01-04-2027,01-05-2027,01-06-2027 | L36: 18060000
A37: 1057532-320-PC26 | B37: PC26 | C37: Bienes y Servicios | D37: Insumos y medicamentos Farmacia COSAM RAHUE | E37: Insumos y Repuestos | F37: 1 | G37: Camilo Martínez | H37: 46023 | I37: Director(S) | J37: 1 | K37: 46023 | L37: 850000
A38: 1057532-321-PC24 | B38: Arrastre | C38: Bienes y Servicios | D38: Convenio - DE SERVICIOS DE MANTENCIÓN PREVENTIVA, CORRECTIVA Y/O REPARATIVA PARA VEHÍCULOS MERCEDES-BENZ DEL SSO Y HOSPITA | E38: Mantenimiento | F38: 1 | G38: Felipe Salvo | H38: 45474 | I38: Encargado Mantenimineto | J38: 24 | K38: 01-01-2025,01-02-2025,01-03-2025,01-04-2025,01-05-2025,01-06-2025,01-07-2025,01-08-2025,01-09-2025,01-10-2025,01-11-2025,01-12-2025,01-01-2026,01-02-2026,01-03-2026,01-04-2026,01-05-2026,01-06-2026,01-07-2026,01-08-2026,01-09-2026,01-10-2026,01-11-2026,01-12-2026 | L38: 150000000
A39: 1057532-321-PC26 | B39: PC26 | C39: Bienes y Servicios | D39: Capacitación en Salud Mental Intercultural COSAM Rahue. | E39: Cafeteria | F39: 2 | G39: Camilo Martínez | H39: 46143 | I39: Director(S) | J39: 1 | K39: 46143 | L39: 450000
A40: 1057532-321-PC26 | B40: PC26 | C40: Bienes y Servicios | D40: Capacitación en Salud Mental Intercultural COSAM Rahue. | E40: Cafeteria | F40: 2 | G40: Camilo Martínez | H40: 46327 | I40: Director(S) | J40: 1 | K40: 46143 | L40: 450000
A41: 1057532-322-PC24 | B41: Arrastre | C41: Bienes y Servicios | D41: Convenio - SERVICIO DE MANEJO, RETIRO, TRANSPORTE Y DISPOSICIÓN FINAL DE RESIDUOS PELIGROSOS Y ESPECIALES | E41: Servicio residuos | F41: 1 | G41: KARIN SCHOLZ | H41: 45505 | I41: JEFA DE DEPTO DE CALIDAD DE VIDA | J41: 24 | K41: 01-01-2025,01-02-2025,01-03-2025,01-04-2025,01-05-2025,01-06-2025,01-07-2025,01-08-2025,01-09-2025,01-10-2025,01-11-2025,01-12-2025,01-01-2026,01-02-2026,01-03-2026,01-04-2026,01-05-2026,01-06-2026,01-07-2026,01-08-2026,01-09-2026,01-10-2026,01-11-2026,01-12-2026 | L41: 397359215
A42: 1057532-322-PC26 | B42: PC26 | C42: Bienes y Servicios | D42: Celebración de We Tripantu en COSAM Rahue 2026 | E42: Cafeteria | F42: 1 | G42: Camilo Martínez | H42: 46174 | I42: Director(S) | J42: 1 | K42: 46174 | L42: 630000
...

Sheet Hoja6
A1: PAC | B1: TIPO PAC | C1: ID Proyecto | D1: Nombre Proyecto | E1: Nombre responsable | F1: Cargo responsable | G1: Cantidad OC | H1: Meses envío OC | I1: Suma de Monto Total Ítem Año 2026
A2: Arrastre | B2: Arrastre | C2: 1057532-156-PC24 | D2: servicios de control de asistencia del servicio de salud osorno | E2: Bruno Ojeda Alvarez | F2: Jefe Depto. Tecnologías de la Información | G2: 36 | H2: 01-01-2024,01-02-2024,01-03-2024,01-04-2024,01-05-2024,01-06-2024,01-07-2024,01-08-2024,01-09-2024,01-10-2024,01-11-2024,01-12-2024,01-01-2025,01-02-2025,01-03-2025,01-04-2025,01-05-2025,01-06-2025,01-07-2025,01-08-2025,01-09-2025,01-10-2025,01-11-2025,01-12-2025,01-01-2026,01-02-2026,01-03-2026,01-04-2026,01-05-2026,01-06-2026,01-07-2026,01-08-2026,01-09-2026,01-10-2026,01-11-2026,01-12-2026 | I2: 30000000
A3: Arrastre | B3: Arrastre | C3: 1057532-162-PC25 | D3: Convenio - de Suministro para adquisición de medicamentos faltantes CENABAST para establecimientos dependientes del SSO. | E3: ELEUTERIO ROMAN | F3: JEFE SUBDEPTO FARMACIA | G3: 24 | H3: 01-05-2025,01-06-2025,01-07-2025,01-08-2025,01-09-2025,01-10-2025,01-11-2025,01-12-2025,01-01-2026,01-02-2026,01-03-2026,01-04-2026,01-05-2026,01-06-2026,01-07-2026,01-08-2026,01-09-2026,01-10-2026,01-11-2026,01-12-2026,01-01-2027,01-02-2027,01-03-2027,01-04-2027 | I3: 75000000
A4: Arrastre | B4: Arrastre | C4: 1057532-163-PC24 | D4: Servicio gestión flota vehicular SSO | E4: Bruno Ojeda Alvarez | F4: Jefe Depto. | G4: 36 | H4: 01-01-2024,01-02-2024,01-03-2024,01-04-2024,01-05-2024,01-06-2024,01-07-2024,01-08-2024,01-09-2024,01-10-2024,01-11-2024,01-12-2024,01-01-2025,01-02-2025,01-03-2025,01-04-2025,01-05-2025,01-06-2025,01-07-2025,01-08-2025,01-09-2025,01-10-2025,01-11-2025,01-12-2025,01-01-2026,01-02-2026,01-03-2026,01-04-2026,01-05-2026,01-06-2026,01-07-2026,01-08-2026,01-09-2026,01-10-2026,01-11-2026,01-12-2026 | I4: 6711996
A5: Arrastre | B5: Arrastre | C5: 1057532-172-PC25 | D5: Convenio - CONVENIO SERVICIO DE ASEO POR 18 MESES, PARA LA DIRECCION DEL SSO Y ESTABLECIMIENTOS DEPENDIENTES DE LA RED ASISTENCIAL | E5: Lorena Torres Castillo | F5: ENCARGADA (S) SECCIÓN DE ADMINISTRACIÓN DE CONTRATOS | G5: 18 | H5: 01-07-2025,01-08-2025,01-09-2025,01-10-2025,01-11-2025,01-12-2025,01-01-2026,01-02-2026,01-03-2026,01-04-2026,01-05-2026,01-06-2026,01-07-2026,01-08-2026,01-09-2026,01-10-2026,01-11-2026,01-12-2026 | I5: 144000000
A6: Arrastre | B6: Arrastre | C6: 1057532-173-PC25 | D6: Convenio - CONVENIO DE ADQUISICION DE KIT POINT OF CARE (POC) CON ARRIENDO DE EQUIPO PARA ANALISIS DE MUESTRAS, SSO | E6: Sofia Reyes | F6: Encargada | G6: 12 | H6: 01-08-2025,01-09-2025,01-10-2025,01-11-2025,01-12-2025,01-01-2026,01-02-2026,01-03-2026,01-04-2026,01-05-2026,01-06-2026,01-07-2026 | I6: 40833335
A7: Arrastre | B7: Arrastre | C7: 1057532-193-PC25 | D7: Convenio - ARRIENDO 159 EQUIPOS PC AIO PARA APOYAR LOS PORCESOS CLINICOS Y ADMINISTRATIVOS | E7: Alvaro Montecinos | F7: Jefe (S) Subdepto. Soporte TIC | G7: 1 | H7: 01-01-2026,01-02-2026,01-03-2026,01-04-2026,01-05-2026,01-06-2026,01-07-2026,01-08-2026,01-09-2026,01-10-2026,01-11-2026,01-12-2026,01-01-2027,01-02-2027,01-03-2027,01-04-2027,01-05-2027,01-06-2027,01-07-2027,01-08-2027,01-09-2027,01-10-2027,01-11-2027,01-12-2027,01-01-2028,01-02-2028,01-03-2028,01-04-2028,01-05-2028,01-06-2028,01-07-2028,01-08-2028 | I7: 74068560
A8: Arrastre | B8: Arrastre | C8: 1057532-193-PC25 | D8: Convenio - ARRIENDO 159 EQUIPOS PC AIO PARA APOYAR LOS PROCESOS CLINICOS Y ADMINISTRATIVOS | E8: Alvaro Montecinos | F8: Jefe (S) Subdepto. Soporte TIC | G8: 32 | H8: 01-01-2026,01-02-2026,01-03-2026,01-04-2026,01-05-2026,01-06-2026,01-07-2026,01-08-2026,01-09-2026,01-10-2026,01-11-2026,01-12-2026,01-01-2027,01-02-2027,01-03-2027,01-04-2027,01-05-2027,01-06-2027,01-07-2027,01-08-2027,01-09-2027,01-10-2027,01-11-2027,01-12-2027,01-01-2028,01-02-2028,01-03-2028,01-04-2028,01-05-2028,01-06-2028,01-07-2028,01-08-2028 | I8: 37034280
A9: Arrastre | B9: Arrastre | C9: 1057532-195-PC25 | D9: Convenio - SERVICIO DE ASEO PARA LA DSSO (BASE SAMU, EDIFICIO PLAZA SUR Y EDIFICIO M. RODRIGUEZ) POR 18 MESES (DESDE 01 JULIO 2025) | E9: Lorena Torres Castillo | F9: Encargada (S) Sección Administración de Contratos | G9: 18 | H9: 01-07-2025,01-08-2025,01-09-2025,01-10-2025,01-11-2025,01-12-2025,01-01-2026,01-02-2026,01-03-2026,01-04-2026,01-05-2026,01-06-2026,01-07-2026,01-08-2026,01-09-2026,01-10-2026,01-11-2026,01-12-2026 | I9: 70333380
A10: Arrastre | B10: Arrastre | C10: 1057532-196-PC25 | D10: Convenio - SERVICIO DE SOPORTE Y MANTENCION RPT VHF SSO (PERIODO DOS AÑOS) | E10: ESTEBAN ALARCON BOHLE | F10: TECNICO RADIOCOMUNICACIONES | G10: 24 | H10: 01-01-2025,01-02-2025,01-03-2025,01-04-2025,01-05-2025,01-06-2025,01-07-2025,01-08-2025,01-09-2025,01-10-2025,01-11-2025,01-12-2025,01-01-2026,01-02-2026,01-03-2026,01-04-2026,01-05-2026,01-06-2026,01-07-2026,01-08-2026,01-09-2026,01-10-2026,01-11-2026,01-12-2026 | I10: 6255504
A11: Arrastre | B11: Arrastre | C11: 1057532-1-PC24 | D11: Sistema control de flota vehicular del Servicio de Salud Osorno | E11: Felipe Salvo Barriga | F11: Enc. Sección Mant. de Vehículos | G11: 36 | H11: 01-01-2024,01-02-2024,01-03-2024,01-04-2024,01-05-2024,01-06-2024,01-07-2024,01-08-2024,01-09-2024,01-10-2024,01-11-2024,01-12-2024,01-01-2025,01-02-2025,01-03-2025,01-04-2025,01-05-2025,01-06-2025,01-07-2025,01-08-2025,01-09-2025,01-10-2025,01-11-2025,01-12-2025,01-01-2026,01-02-2026,01-03-2026,01-04-2026,01-05-2026,01-06-2026,01-07-2026,01-08-2026,01-09-2026,01-10-2026,01-11-2026,01-12-2026 | I11: 6712008
A12: Arrastre | B12: Arrastre | C12: 1057532-209-PC25 | D12: Convenio - ADQUISICION DE 3 CUPOS DE RESIDENCIA PROTEGIDA PARA EL SERVICIO DE SALUD OSORNO EN LA PROVINCIA DE CONCEPCIÓN | E12: Angelo Palma | F12: Jefe (s) Subdepto. Gestión Clínica y Administrativa Red Temática de Salud Mental de Especialidad | G12: 24 | H12: 01-01-2025,01-02-2025,01-03-2025,01-04-2025,01-05-2025,01-06-2025,01-07-2025,01-08-2025,01-09-2025,01-10-2025,01-11-2025,01-12-2025,01-01-2026,01-02-2026,01-03-2026,01-04-2026,01-05-2026,01-06-2026,01-07-2026,01-08-2026,01-09-2026,01-10-2026,01-11-2026,01-12-2026 | I12: 48115128
A13: Arrastre | B13: Arrastre | C13: 1057532-210-PC25 | D13: Convenio - ADQUISICION DE 12 CUPOS DE RESIDENCIA PROTEGIDA PARA EL SERVICIO DE SALUD OSORNO EN LA CIUDAD DE OSORNO | E13: Angelo Palma | F13: Jefe (s) Subdepto. Gestión Clínica y Administrativa Red Temática de Salud Mental de Especialidad | G13: 24 | H13: 01-01-2025,01-02-2025,01-03-2025,01-04-2025,01-05-2025,01-06-2025,01-07-2025,01-08-2025,01-09-2025,01-10-2025,01-11-2025,01-12-2025,01-01-2026,01-02-2026,01-03-2026,01-04-2026,01-05-2026,01-06-2026,01-07-2026,01-08-2026,01-09-2026,01-10-2026,01-11-2026,01-12-2026 | I13: 237155100
... A71: Arrastre | B71: Arrastre | C71: 1077241-53-PC25 | D71: Convenio - Servicio de arriendo e informes de teleelectrocardiografía (sospecha IAM), para 13 establecimientos de urgencia de APS | E71: Consuelo Cordova | F71: jefa subdepto gestión de programas en curso de vida | G71: 12 | H71: 01-02-2026,01-03-2026,01-04-2026,01-05-2026,01-06-2026,01-07-2026,01-08-2026,01-09-2026,01-10-2026,01-11-2026,01-12-2026,01-01-2027 | I71: 30800000
A72: PC26 | B72: Activos Fijos | C72: 1057922-10-PC26 | D72: REPOSICION CESFAM CON SAR RAHUE ALTO, OSORNO | E72: Maria Elena Muñoz | F72: Jefa (S) Sub. Dpto. De Inversiones De Equipos Y Equipamiento | G72: 1 | H72: 46113 | I72: 1578831000
A73: PC26 | B73: Activos Fijos | C73: 1057922-11-PC26 | D73: HABILITACION ANGIOGRAFO HOSPITAL BASE DE OSORNO | E73: Maria Elena Muñoz | F73: Jefa (S) Sub. Dpto. De Inversiones De Equipos Y Equipamiento | G73: 1 | H73: 46113 | I73: 1969068000
A74: PC26 | B74: Activos Fijos | C74: 1057922-12-PC26 | D74: CONSTRUCCION COSAM RAHUE, COMUNA OSORNO | E74: Maria Elena Muñoz | F74: Jefa (S) Sub. Dpto. De Inversiones De Equipos Y Equipamiento | G74: 1 | H74: 46113 | I74: 18632000
A75: PC26 | B75: Activos Fijos | C75: 1057922-13-PC26 | D75: SUBTÍTULO 29 SECTORIAL 2026 | E75: Maria Elena Muñoz | F75: Jefa (S) Sub. Dpto. De Inversiones De Equipos Y Equipamiento | G75: 1 | H75: 46113 | I75: 280000000
A76: PC26 | B76: Activos Fijos | C76: 1057922-14-PC26 | D76: SUBTÍTULO 29 OPERACIONAL SSO 2026 | E76: Maria Elena Muñoz | F76: Jefa (S) Sub. Dpto. De Inversiones De Equipos Y Equipamiento | G76: 1 | H76: 46143 | I76: 61000000
A77: PC26 | B77: Activos Fijos | C77: 1057922-15-PC26 | D77: Equipamiento Ergonómico - Sillas | E77: Venecia Recabarren | F77: Jefatura Unidad Prev. Riesgos | G77: 1 | H77: 46023 | I77: 1000000
A78: PC26 | B78: Activos Fijos | C78: 1057922-16-PC26 | D78: Adquisición de micrófono y cámara para videoconferencias del Centro Comunitario Kümelen | E78: Luis Flores | F78: Coordinador | G78: 1 | H78: 46054 | I78: 250000
A79: PC26 | B79: Activos Fijos | C79: 1057922-17-PC26 | D79: Adquisición de megáfonos y gabinetes para la comunicación en emergencias, gestión de riesgos y protección de equipos | E79: Yuvit Garcia-Chacur | F79: DIRECTORA | G79: 1 | H79: 46023 | I79: 780000
A80: PC26 | B80: Activos Fijos | C80: 1057922-18-PC26 | D80: REPOSICION CECOSF EL ENCANTO, COMUNA DE PUYEHUE | E80: Maria Elena Muñoz | F80: Jefa (S) Sub. Dpto. De Inversiones De Equipos Y Equipamiento | G80: 1 | H80: 46113 | I80: 6773000
A81: PC26 | B81: Activos Fijos | C81: 1057922-19-PC26 | D81: Adquisición de productos e insumos para el programa de control y eliminación de la Tuberculosis | E81: NMaria Paz Gomez | F81: Referente Programa De Tuberculosis | G81: 1 | H81: 46174 | I81: 19000000
A82: PC26 | B82: Activos Fijos | C82: 1057922-20-PC26 | D82: Adquisición de herramientas | E82: Pedro Fritz | F82: Director | G82: 1 | H82: 46023 | I82: 300000
A83: PC26 | B83: Activos Fijos | C83: 1057922-21-PC26 | D83: Adquisicion equipamiento Servidor NAS y almacenamiento extra para respaldo y seguridad de la información | E83: Alejandro Nuñez | F83: Encargado Gestión De Sistemas | G83: 1 | H83: 46082 | I83: 16000000
... A106: PC26 | B106: Administración de Fondos | C106: 1077241-112-PC26 | D106: ARTICULOS DE COCINA RESIDENCIAL ? CONVENIO SENDA | E106: Carolina Silva | F106: Encargada De Compras | G106: 1 | H106: 46143 | I106: 280008
A107: PC26 | B107: Administración de Fondos | C107: 1077241-61-PC26 | D107: Adquisición de prestaciones de rehabilitación integral a niños, niñas y adolescentes con Trastorno del Espectro Autista | E107: Karin Avila | F107: Referente Rehabilitación Integral | G107: 10 | H107: 01-03-2026,01-04-2026,01-05-2026,01-06-2026,01-07-2026,01-08-2026,01-09-2026,01-10-2026,01-11-2026,01-12-2026 | I107: 56320000
A108: PC26 | B108: Administración de Fondos | C108: 1077241-62-PC26 | D108: PRAPS Fondo de Farmacia para enfermedades crónicas no transmisibles en APS (FOFAR) | E108: Chessarina Tuchie Fischer | F108: Encargada Programa Fofar | G108: 1 | H108: 46113 | I108: 30000000
A109: PC26 | B109: Administración de Fondos | C109: 1077241-62-PC26 | D109: PRAPS Fondo de Farmacia para enfermedades crónicas no transmisibles en APS (FOFAR) | E109: Chessarina Tuchie Fischer | F109: Encargada Programa Fofar | G109: 1 | H109: 46143 | I109: 30000000
A110: PC26 | B110: Administración de Fondos | C110: 1077241-63-PC26 | D110: Adquisición de insumos para la atención en domicilio del Equipo Rehabilitación Rural SSO. | E110: Karin Avila | F110: Referente Rehabilitación Integral | G110: 1 | H110: 46082 | I110: 410000
A111: PC26 | B111: Administración de Fondos | C111: 1077241-64-PC26 | D111: Ceremonia de alta SENDA-PAI COSAM Rahue 2026 | E111: Camilo Martínez | F111: Director(S) | G111: 1 | H111: 46235 | I111: 225000
A112: PC26 | B112: Administración de Fondos | C112: 1077241-65-PC26 | D112: Anilladora e insumos para preparación de material Cosam Rahue. Fondo extrapresupuestarios SENDA PAI | E112: Camilo Martínez | F112: Director(S) | G112: 1 | H112: 46054 | I112: 260000
A113: PC26 | B113: Administración de Fondos | C113: 1077241-66-PC26 | D113: Jornada de Autocuidado funcionarios COSAM Rahue, con cargo a fondo extrapresupuestario SENDA-PAI | E113: Camilo Martínez | F113: Director(S) | G113: 1 | H113: 46174 | I113: 450000
A114: PC26 | B114: Administración de Fondos | C114: 1077241-66-PC26 | D114: Jornada de Autocuidado funcionarios COSAM Rahue, con cargo a fondo extrapresupuestario SENDA-PAI | E114: Camilo Martínez | F114: Director(S) | G114: 1 | H114: 46357 | I114: 450000
A115: PC26 | B115: Administración de Fondos | C115: 1077241-67-PC26 | D115: Celebración fiestas patrias usuarios y cuidadores COSAM RAHUE. | E115: Camilo Martínez | F115: Director(S) | G115: 1 | H115: 46266 | I115: 625000
A116: PC26 | B116: Administración de Fondos | C116: 1077241-68-PC26 | D116: Adquisición de insumos para la atención en domicilio del Equipo Rehabilitación Rural SSO (material Ergoterapia) | E116: Karin Avila | F116: Referente Rehabilitación Integral | G116: 1 | H116: 46082 | I116: 150000
A117: PC26 | B117: Administración de Fondos | C117: 1077241-69-PC26 | D117: Insumos cafetería actividades con usuarios Cosam Rahue y comunidad 2026, fondo extrapresupuestario SENDA PAI | E117: Camilo Martínez | F117: Director(S) | G117: 1 | H117: 46023 | I117: 2772880
A118: PC26 | B118: Administración de Fondos | C118: 1077241-70-PC26 | D118: INSUMOS ESCRITORIO COSAM RAHUE, FONDO EXTRAPRESUPUESTARIO SENDA-PAI | E118: Camilo Martínez | F118: Director(S) | G118: 1 | H118: 46082 | I118: 1468231
A119: PC26 | B119: Administración de Fondos | C119: 1077241-71-PC26 | D119: Compra de tintas de repuesto impresoras Cosam Rahue | E119: Camilo Martínez | F119: Director(S) | G119: 1 | H119: 46113 | I119: 350000
...

Sheet Hoja16
A3: Unidad de Compra | B3: Proyectos | C3: Monto
A4: Bienes y Servicios | B4: 238 | C4: 1932801598
A5: Activos Fijos | B5: 18 | C5: 4545805005
A6: Administración de Fondos | B6: 47 | C6: 216217147
A7: Bienestar | B7: 1 | C7: 156000000
A8: Compras Convenio GORE Region de Los Lagos | B8: 16 | C8: 1438588008
A9: Obras Civiles | B9: 14 | C9: 7264673295
A10: Proyectos de Arrastre | B10: 59 | C10: 6588447864
A11: Total general | B11: 393 | C11: 22142532917

Sheet TD
A1: PAC | B1: TIPO PAC | C1: ID Proyecto | D1: Nombre Proyecto | E1: Nombre responsable | F1: Cargo responsable | G1: Suma de Monto Total Ítem Año 2026
A2: Arrastre | B2: Arrastre | C2: 1057532-156-PC24 | D2: servicios de control de asistencia del servicio de salud osorno | E2: Bruno Ojeda Alvarez | F2: Jefe Depto. Tecnologías de la Información | G2: 30000000
A3: Arrastre | B3: Arrastre | C3: 1057532-162-PC25 | D3: Convenio - de Suministro para adquisición de medicamentos faltantes CENABAST para establecimientos dependientes del SSO. | E3: ELEUTERIO ROMAN | F3: JEFE SUBDEPTO FARMACIA | G3: 75000000
A4: Arrastre | B4: Arrastre | C4: 1057532-163-PC24 | D4: Servicio gestión flota vehicular SSO | E4: Bruno Ojeda Alvarez | F4: Jefe Depto. | G4: 6711996
A5: Arrastre | B5: Arrastre | C5: 1057532-172-PC25 | D5: Convenio - CONVENIO SERVICIO DE ASEO POR 18 MESES, PARA LA DIRECCION DEL SSO Y ESTABLECIMIENTOS DEPENDIENTES DE LA RED ASISTENCIAL | E5: Lorena Torres Castillo | F5: ENCARGADA (S) SECCIÓN DE ADMINISTRACIÓN DE CONTRATOS | G5: 144000000
A6: Arrastre | B6: Arrastre | C6: 1057532-173-PC25 | D6: Convenio - CONVENIO DE ADQUISICION DE KIT POINT OF CARE (POC) CON ARRIENDO DE EQUIPO PARA ANALISIS DE MUESTRAS, SSO | E6: Sofia Reyes | F6: Encargada | G6: 40833335
A7: Arrastre | B7: Arrastre | C7: 1057532-193-PC25 | D7: Convenio - ARRIENDO 159 EQUIPOS PC AIO PARA APOYAR LOS PORCESOS CLINICOS Y ADMINISTRATIVOS | E7: Alvaro Montecinos | F7: Jefe (S) Subdepto. Soporte TIC | G7: 111102840
A8: Arrastre | B8: Arrastre | C8: 1057532-195-PC25 | D8: Convenio - SERVICIO DE ASEO PARA LA DSSO (BASE SAMU, EDIFICIO PLAZA SUR Y EDIFICIO M. RODRIGUEZ) POR 18 MESES (DESDE 01 JULIO 2025) | E8: Lorena Torres Castillo | F8: Encargada (S) Sección Administración de Contratos | G8: 70333380
A9: Arrastre | B9: Arrastre | C9: 1057532-196-PC25 | D9: Convenio - SERVICIO DE SOPORTE Y MANTENCION RPT VHF SSO (PERIODO DOS AÑOS) | E9: ESTEBAN ALARCON BOHLE | F9: TECNICO RADIOCOMUNICACIONES | G9: 6255504
A10: Arrastre | B10: Arrastre | C10: 1057532-1-PC24 | D10: Sistema control de flota vehicular del Servicio de Salud Osorno | E10: Felipe Salvo Barriga | F10: Enc. Sección Mant. de Vehículos | G10: 6712008
A11: Arrastre | B11: Arrastre | C11: 1057532-209-PC25 | D11: Convenio - ADQUISICION DE 3 CUPOS DE RESIDENCIA PROTEGIDA PARA EL SERVICIO DE SALUD OSORNO EN LA PROVINCIA DE CONCEPCIÓN | E11: Angelo Palma | F11: Jefe (s) Subdepto. Gestión Clínica y Administrativa Red Temática de Salud Mental de Especialidad | G11: 48115128
A12: Arrastre | B12: Arrastre | C12: 1057532-210-PC25 | D12: Convenio - ADQUISICION DE 12 CUPOS DE RESIDENCIA PROTEGIDA PARA EL SERVICIO DE SALUD OSORNO EN LA CIUDAD DE OSORNO | E12: Angelo Palma | F12: Jefe (s) Subdepto. Gestión Clínica y Administrativa Red Temática de Salud Mental de Especialidad | G12: 237155100
A13: Arrastre | B13: Arrastre | C13: 1057532-211-PC25 | D13: Convenio - ADQUISICION DE 10 CUPOS RESIDENCIA PROTEGIDA DE ALTA COMPLEJIDAD PARA EL SERVICIO DE SALUD OSORNO DE LA CIUDAD DE OSORNO | E13: Angelo Palma | F13: Jefe (s) Subdepto. Gestión Clínica y Administrativa Red Temática de Salud Mental de Especialidad | G13: 284700000
... A394: PC26 | B394: Obras Civiles | C394: 1057976-9-PC26 | D394: Contratación de Visita a Obra 2026 de las Consultorías: Especialidades y Arquitectura Obra CESFAM Bahía Mansa | E394: Rodrigo Neira | F394: Itos | G394: 9814756

Sheet Oficial Panel
A1: ID Proyecto | B1: Nombre Proyecto | C1: Nombre responsable | D1: Cargo responsable
A2: 1057532-156-PC24 | B2: servicios de control de asistencia del servicio de salud osorno | C2: Bruno Ojeda Alvarez | D2: Jefe Depto. Tecnologías de la Información
A3: 1057532-162-PC25 | B3: Convenio - de Suministro para adquisición de medicamentos faltantes CENABAST para establecimientos dependientes del SSO. | C3: ELEUTERIO ROMAN | D3: JEFE SUBDEPTO FARMACIA
A4: 1057532-163-PC24 | B4: Servicio gestión flota vehicular SSO | C4: Bruno Ojeda Alvarez | D4: Jefe Depto.
A5: 1057532-172-PC25 | B5: Convenio - CONVENIO SERVICIO DE ASEO POR 18 MESES, PARA LA DIRECCION DEL SSO Y ESTABLECIMIENTOS DEPENDIENTES DE LA RED ASISTENCIAL | C5: Lorena Torres Castillo | D5: ENCARGADA (S) SECCIÓN DE ADMINISTRACIÓN DE CONTRATOS
A6: 1057532-173-PC25 | B6: Convenio - CONVENIO DE ADQUISICION DE KIT POINT OF CARE (POC) CON ARRIENDO DE EQUIPO PARA ANALISIS DE MUESTRAS, SSO | C6: Sofia Reyes | D6: Encargada
A7: 1057532-193-PC25 | B7: Convenio - ARRIENDO 159 EQUIPOS PC AIO PARA APOYAR LOS PORCESOS CLINICOS Y ADMINISTRATIVOS | C7: Alvaro Montecinos | D7: Jefe (S) Subdepto. Soporte TIC
A8: 1057532-193-PC25 | B8: Convenio - ARRIENDO 159 EQUIPOS PC AIO PARA APOYAR LOS PROCESOS CLINICOS Y ADMINISTRATIVOS | C8: Alvaro Montecinos | D8: Jefe (S) Subdepto. Soporte TIC
A9: 1057532-195-PC25 | B9: Convenio - SERVICIO DE ASEO PARA LA DSSO (BASE SAMU, EDIFICIO PLAZA SUR Y EDIFICIO M. RODRIGUEZ) POR 18 MESES (DESDE 01 JULIO 2025) | C9: Lorena Torres Castillo | D9: Encargada (S) Sección Administración de Contratos
A10: 1057532-196-PC25 | B10: Convenio - SERVICIO DE SOPORTE Y MANTENCION RPT VHF SSO (PERIODO DOS AÑOS) | C10: ESTEBAN ALARCON BOHLE | D10: TECNICO RADIOCOMUNICACIONES
A11: 1057532-1-PC24 | B11: Sistema control de flota vehicular del Servicio de Salud Osorno | C11: Felipe Salvo Barriga | D11: Enc. Sección Mant. de Vehículos
A12: 1057532-209-PC25 | B12: Convenio - ADQUISICION DE 3 CUPOS DE RESIDENCIA PROTEGIDA PARA EL SERVICIO DE SALUD OSORNO EN LA PROVINCIA DE CONCEPCIÓN | C12: Angelo Palma | D12: Jefe (s) Subdepto. Gestión Clínica y Administrativa Red Temática de Salud Mental de Especialidad
... A395: 1180747-9-PC26 | B395: Consultorías adecuación Diseño PSR Hueyusca, comuna de Purranque. | C395: Mario Barrientos | D395: Jefe Subdepto. Diseño De Infraestructura De Salud

Sheet Oficial
A1: ID Proyecto | B1: Tipo PAC | C1: Memo | D1: Unidad de Compra | E1: Nombre Proyecto | F1: Fecha de Compra | G1: Cantidad de Ítems | H1: Nombre ítem | I1: Monto Total item | J1: Nombre responsable | K1: Cargo responsable | L1: Departamento | M1: Subdirección | N1: Departamento_SHORT | O1: CANT OC | P1: FECHA OC
A2: 1057532-496-PC26 | B2: PC26 | C2: Bienes y Servicios | D2: Bienes y Servicios | E2: Adquisicion Licencias de Software GstarCAD por 24 meses | F2: 46174 | G2: 1 | H2: Software | I2: 15000018 | J2: Alejandro Nuñez | K2: Encargado Gestión De Sistemas | L2: DEPARTAMENTO DE TECNOLOGIAS DE LA INFORMACION Y COMUNICACION | M2: SUBDIRECCION ADMINISTRATIVA | N2: TIC
A3: 1057532-497-PC26 | B3: PC26 | C3: Bienes y Servicios | D3: Bienes y Servicios | E3: Adquisicion Licencias de Software ArchiCAD por 24 meses | F3: 46174 | G3: 1 | H3: Licencia | I3: 30000000 | J3: Alejandro Nuñez | K3: Encargado Gestión De Sistemas | L3: DEPARTAMENTO DE TECNOLOGIAS DE LA INFORMACION Y COMUNICACION | M3: SUBDIRECCION ADMINISTRATIVA | N3: TIC
A4: 1057532-525-PC26 | B4: PC26 | C4: Bienes y Servicios | D4: Bienes y Servicios | E4: ADQUISICIÓN DISPOSITIVOS DE ALMACENAMIENTO PARA HABILITACION DE EQUIPOS COMPUTACIONALES | F4: 46082 | G4: 1 | H4: Disco Duros | I4: 3550000 | J4: Alejandro Nuñez | K4: Encargado Gestión De Sistemas | L4: DEPARTAMENTO DE TECNOLOGIAS DE LA INFORMACION Y COMUNICACION | M4: SUBDIRECCION ADMINISTRATIVA | N4: TIC
A5: 1057922-21-PC26 | B5: PC26 | C5: Activos Fijos | D5: Activos Fijos | E5: Adquisicion equipamiento Servidor NAS y almacenamiento extra para respaldo y seguridad de la información | F5: 46082 | G5: 2 | H5: Disco Duro | I5: 1000000 | J5: Alejandro Nuñez | K5: Encargado Gestión De Sistemas | L5: DEPARTAMENTO DE TECNOLOGIAS DE LA INFORMACION Y COMUNICACION | M5: SUBDIRECCION ADMINISTRATIVA | N5: TIC
A6: 1057922-21-PC26 | B6: PC26 | C6: Activos Fijos | D6: Activos Fijos | E6: Adquisicion equipamiento Servidor NAS y almacenamiento extra para respaldo y seguridad de la información | F6: 46082 | G6: 2 | H6: Servidor | I6: 15000000 | J6: Alejandro Nuñez | K6: Encargado Gestión De Sistemas | L6: DEPARTAMENTO DE TECNOLOGIAS DE LA INFORMACION Y COMUNICACION | M6: SUBDIRECCION ADMINISTRATIVA | N6: TIC
A7: 1057532-193-PC25 | B7: Arrastre | C7: Arrastre | D7: Bienes y Servicios | E7: Convenio - ARRIENDO 159 EQUIPOS PC AIO PARA APOYAR LOS PORCESOS CLINICOS Y ADMINISTRATIVOS | F7: 45870 | G7: 2 | H7: Insumos | I7: 74068560 | J7: Alvaro Montecinos | K7: Jefe (S) Subdepto. Soporte TIC | L7: DEPARTAMENTO DE TECNOLOGIAS DE LA INFORMACION Y COMUNICACION | M7: SUBDIRECCION ADMINISTRATIVA | N7: TIC
A8: 1057532-193-PC25 | B8: Arrastre | C8: Arrastre | D8: Bienes y Servicios | E8: Convenio - ARRIENDO 159 EQUIPOS PC AIO PARA APOYAR LOS PROCESOS CLINICOS Y ADMINISTRATIVOS | F8: 45992 | G8: 2 | H8: Insumos | I8: 37034280 | J8: Alvaro Montecinos | K8: Jefe (S) Subdepto. Soporte TIC | L8: DEPARTAMENTO DE TECNOLOGIAS DE LA INFORMACION Y COMUNICACION | M8: SUBDIRECCION ADMINISTRATIVA | N8: TIC
A9: 1057532-581-PC26 | B9: PC26 | C9: Bienes y Servicios | D9: Bienes y Servicios | E9: CONTRIBUYENDO A LA POLITICA PÚBLICA EN REPARACIÓN CON USUARIOS/AS PRAIS | F9: 46082 | G9: 23 | H9: Alcohol gel | I9: 35000 | J9: Ana María Diaz | K9: Coordinadora | L9: PRAIS | M9: SUBDIRECCION DE GESTION ASISTENCIAL | N9: PRAIS
A10: 1057532-581-PC26 | B10: PC26 | C10: Bienes y Servicios | D10: Bienes y Servicios | E10: CONTRIBUYENDO A LA POLITICA PÚBLICA EN REPARACIÓN CON USUARIOS/AS PRAIS | F10: 46082 | G10: 23 | H10: Alimentación | I10: 490000 | J10: Ana María Diaz | K10: Coordinadora | L10: PRAIS | M10: SUBDIRECCION DE GESTION ASISTENCIAL | N10: PRAIS
A11: 1057532-581-PC26 | B11: PC26 | C11: Bienes y Servicios | D11: Bienes y Servicios | E11: CONTRIBUYENDO A LA POLITICA PÚBLICA EN REPARACIÓN CON USUARIOS/AS PRAIS | F11: 46082 | G11: 23 | H11: Artículos de librería | I11: 308000 | J11: Ana María Diaz | K11: Coordinadora | L11: PRAIS | M11: SUBDIRECCION DE GESTION ASISTENCIAL | N11: PRAIS
A12: 1057532-581-PC26 | B12: PC26 | C12: Bienes y Servicios | D12: Bienes y Servicios | E12: CONTRIBUYENDO A LA POLITICA PÚBLICA EN REPARACIÓN CON USUARIOS/AS PRAIS | F12: 46082 | G12: 23 | H12: Artículos de Oficina | I12: 145040 | J12: Ana María Diaz | K12: Coordinadora | L12: PRAIS | M12: SUBDIRECCION DE GESTION ASISTENCIAL | N12: PRAIS
A13: 1057532-581-PC26 | B13: PC26 | C13: Bienes y Servicios | D13: Bienes y Servicios | E13: CONTRIBUYENDO A LA POLITICA PÚBLICA EN REPARACIÓN CON USUARIOS/AS PRAIS | F13: 46082 | G13: 23 | H13: Bloqueador solar | I13: 35000 | J13: Ana María Diaz | K13: Coordinadora | L13: PRAIS | M13: SUBDIRECCION DE GESTION ASISTENCIAL | N13: PRAIS
... A704: 1077241-51-PC25 | B704: Arrastre | C704: Arrastre | D704: Administración de Fondos | E704: Convenio - Servicio movilización COSAM Rahue periodo 2026. (Financiamiento a través de fondo extrapresupuestario SENDA PAI) | F704: 45839 | G704: 1 | H704: Movilizacion | I704: 17416663 | J704: Yuvit García-Chacur | K704: DIRECTORA | L704: CENTRO DE SALUD MENTAL COMUNITARIO COSAM RAHUE | M704: SUBDIRECCION DE GESTION ASISTENCIAL | N704: SALUD MENTAL

Sheet OficialReal
A1: ID Proyecto | B1: PAC | C1: Unidad de Compra | D1: Nombre Proyecto | E1: Nombre ítem | F1: Cantidad de Ítems | G1: Nombre responsable | H1: Fecha de Inicio Compra | I1: Cargo responsable | J1: Cantidad OC | K1: Meses envío OC | L1: Suma de Monto Total Ítem Año 2026 | M1: Departamento | N1: Subdirección | O1: Departamento_SHORT | P1: Ejecución
A2: 1057532-156-PC24 | B2: Arrastre | C2: Bienes y Servicios | D2: servicios de control de asistencia del servicio de salud osorno | E2: Servicio Control Asistencia | F2: 2 | G2: Bruno Ojeda Alvarez | H2: 45292 | I2: Jefe Depto. Tecnologías de la Información | J2: 36 | K2: 01-01-2024,01-02-2024,01-03-2024,01-04-2024,01-05-2024,01-06-2024,01-07-2024,01-08-2024,01-09-2024,01-10-2024,01-11-2024,01-12-2024,01-01-2025,01-02-2025,01-03-2025,01-04-2025,01-05-2025,01-06-2025,01-07-2025,01-08-2025,01-09-2025,01-10-2025,01-11-2025,01-12-2025,01-01-2026,01-02-2026,01-03-2026,01-04-2026,01-05-2026,01-06-2026,01-07-2026,01-08-2026,01-09-2026,01-10-2026,01-11-2026,01-12-2026 | L2: 30000000 | M2: DEPARTAMENTO DE TECNOLOGIAS DE LA INFORMACION Y COMUNICACION | N2: SUBDIRECCION ADMINISTRATIVA | O2: TIC | P2: No Ejecutado
A3: 1057532-162-PC25 | B3: Arrastre | C3: Bienes y Servicios | D3: Convenio - de Suministro para adquisición de medicamentos faltantes CENABAST para establecimientos dependientes del SSO. | E3: Medicamentos | F3: 1 | G3: ELEUTERIO ROMAN | H3: 45748 | I3: JEFE SUBDEPTO FARMACIA | J3: 24 | K3: 01-05-2025,01-06-2025,01-07-2025,01-08-2025,01-09-2025,01-10-2025,01-11-2025,01-12-2025,01-01-2026,01-02-2026,01-03-2026,01-04-2026,01-05-2026,01-06-2026,01-07-2026,01-08-2026,01-09-2026,01-10-2026,01-11-2026,01-12-2026,01-01-2027,01-02-2027,01-03-2027,01-04-2027 | L3: 75000000 | M3: DEPARTAMENTO DE OBRAS Y GESTION FINANCIERA DE INVERSIONES | N3: SUBDIRECCION ADMINISTRATIVA | O3: OBRAS Y GESTIÓN FINANCIERA DE INVERSIONES | P3: No Ejecutado
A4: 1057532-163-PC24 | B4: Arrastre | C4: Bienes y Servicios | D4: Servicio gestión flota vehicular SSO | E4: Control Flota | F4: 2 | G4: Bruno Ojeda Alvarez | H4: 45200 | I4: Jefe Depto. | J4: 36 | K4: 01-01-2024,01-02-2024,01-03-2024,01-04-2024,01-05-2024,01-06-2024,01-07-2024,01-08-2024,01-09-2024,01-10-2024,01-11-2024,01-12-2024,01-01-2025,01-02-2025,01-03-2025,01-04-2025,01-05-2025,01-06-2025,01-07-2025,01-08-2025,01-09-2025,01-10-2025,01-11-2025,01-12-2025,01-01-2026,01-02-2026,01-03-2026,01-04-2026,01-05-2026,01-06-2026,01-07-2026,01-08-2026,01-09-2026,01-10-2026,01-11-2026,01-12-2026 | L4: 6711996 | M4: DEPARTAMENTO DE TECNOLOGIAS DE LA INFORMACION Y COMUNICACION | N4: SUBDIRECCION ADMINISTRATIVA | O4: TIC | P4: No Ejecutado
A5: 1057532-172-PC25 | B5: Arrastre | C5: Bienes y Servicios | D5: Convenio - CONVENIO SERVICIO DE ASEO POR 18 MESES, PARA LA DIRECCION DEL SSO Y ESTABLECIMIENTOS DEPENDIENTES DE LA RED ASISTENCIAL | E5: Aseo | F5: 1 | G5: Lorena Torres Castillo | H5: 45839 | I5: ENCARGADA (S) SECCIÓN DE ADMINISTRACIÓN DE CONTRATOS | J5: 18 | K5: 01-07-2025,01-08-2025,01-09-2025,01-10-2025,01-11-2025,01-12-2025,01-01-2026,01-02-2026,01-03-2026,01-04-2026,01-05-2026,01-06-2026,01-07-2026,01-08-2026,01-09-2026,01-10-2026,01-11-2026,01-12-2026 | L5: 144000000 | M5: DEPARTAMENTO DE ABASTECIMIENTO Y OPERACIONES | N5: SUBDIRECCION ADMINISTRATIVA | O5: ABASTECIMIENTO Y OPERACIONES | P5: No Ejecutado
A6: 1057532-173-PC25 | B6: Arrastre | C6: Bienes y Servicios | D6: Convenio - CONVENIO DE ADQUISICION DE KIT POINT OF CARE (POC) CON ARRIENDO DE EQUIPO PARA ANALISIS DE MUESTRAS, SSO | E6: Equipo | F6: 1 | G6: Sofia Reyes | H6: 45839 | I6: Encargada | J6: 12 | K6: 01-08-2025,01-09-2025,01-10-2025,01-11-2025,01-12-2025,01-01-2026,01-02-2026,01-03-2026,01-04-2026,01-05-2026,01-06-2026,01-07-2026 | L6: 40833335 | M6: DEPARTAMENTO ARTICULACION DE LA RED ASISTENCIAL | N6: SUBDIRECCION DE GESTION ASISTENCIAL | O6: ARTICULACION DE LA RED ASISTENCIAL | P6: No Ejecutado
A7: 1057532-193-PC25 | B7: Arrastre | C7: Bienes y Servicios | D7: Convenio - ARRIENDO 159 EQUIPOS PC AIO PARA APOYAR LOS PORCESOS CLINICOS Y ADMINISTRATIVOS | E7: Insumos | F7: 2 | G7: Alvaro Montecinos | H7: 45870 | I7: Jefe (S) Subdepto. Soporte TIC | J7: 1 | K7: 01-01-2026,01-02-2026,01-03-2026,01-04-2026,01-05-2026,01-06-2026,01-07-2026,01-08-2026,01-09-2026,01-10-2026,01-11-2026,01-12-2026,01-01-2027,01-02-2027,01-03-2027,01-04-2027,01-05-2027,01-06-2027,01-07-2027,01-08-2027,01-09-2027,01-10-2027,01-11-2027,01-12-2027,01-01-2028,01-02-2028,01-03-2028,01-04-2028,01-05-2028,01-06-2028,01-07-2028,01-08-2028 | L7: 74068560 | M7: DEPARTAMENTO DE TECNOLOGIAS DE LA INFORMACION Y COMUNICACION | N7: SUBDIRECCION ADMINISTRATIVA | O7: TIC | P7: No Ejecutado
A8: 1057532-193-PC25 | B8: Arrastre | C8: Bienes y Servicios | D8: Convenio - ARRIENDO 159 EQUIPOS PC AIO PARA APOYAR LOS PROCESOS CLINICOS Y ADMINISTRATIVOS | E8: Insumos | F8: 2 | G8: Alvaro Montecinos | H8: 45992 | I8: Jefe (S) Subdepto. Soporte TIC | J8: 32 | K8: 01-01-2026,01-02-2026,01-03-2026,01-04-2026,01-05-2026,01-06-2026,01-07-2026,01-08-2026,01-09-2026,01-10-2026,01-11-2026,01-12-2026,01-01-2027,01-02-2027,01-03-2027,01-04-2027,01-05-2027,01-06-2027,01-07-2027,01-08-2027,01-09-2027,01-10-2027,01-11-2027,01-12-2027,01-01-2028,01-02-2028,01-03-2028,01-04-2028,01-05-2028,01-06-2028,01-07-2028,01-08-2028 | L8: 37034280 | M8: DEPARTAMENTO DE TECNOLOGIAS DE LA INFORMACION Y COMUNICACION | N8: SUBDIRECCION ADMINISTRATIVA | O8: TIC | P8: No Ejecutado
A9: 1057532-195-PC25 | B9: Arrastre | C9: Bienes y Servicios | D9: Convenio - SERVICIO DE ASEO PARA LA DSSO (BASE SAMU, EDIFICIO PLAZA SUR Y EDIFICIO M. RODRIGUEZ) POR 18 MESES (DESDE 01 JULIO 2025) | E9: Aseo | F9: 2 | G9: Lorena Torres Castillo | H9: 45658 | I9: Encargada (S) Sección Administración de Contratos | J9: 18 | K9: 01-07-2025,01-08-2025,01-09-2025,01-10-2025,01-11-2025,01-12-2025,01-01-2026,01-02-2026,01-03-2026,01-04-2026,01-05-2026,01-06-2026,01-07-2026,01-08-2026,01-09-2026,01-10-2026,01-11-2026,01-12-2026 | L9: 70333380 | M9: DEPARTAMENTO DE ABASTECIMIENTO Y OPERACIONES | N9: SUBDIRECCION ADMINISTRATIVA | O9: ABASTECIMIENTO Y OPERACIONES | P9: No Ejecutado
A10: 1057532-196-PC25 | B10: Arrastre | C10: Bienes y Servicios | D10: Convenio - SERVICIO DE SOPORTE Y MANTENCION RPT VHF SSO (PERIODO DOS AÑOS) | E10: Mantenimiento | F10: 2 | G10: ESTEBAN ALARCON BOHLE | H10: 45658 | I10: TECNICO RADIOCOMUNICACIONES | J10: 24 | K10: 01-01-2025,01-02-2025,01-03-2025,01-04-2025,01-05-2025,01-06-2025,01-07-2025,01-08-2025,01-09-2025,01-10-2025,01-11-2025,01-12-2025,01-01-2026,01-02-2026,01-03-2026,01-04-2026,01-05-2026,01-06-2026,01-07-2026,01-08-2026,01-09-2026,01-10-2026,01-11-2026,01-12-2026 | L10: 6255504 | M10: SUB. DPTO. GESTION DEL RIESGO EN EMERGENCIAS, DESASTRES Y TELECOMUNICACIONES | N10: DIRECCIÓN | O10: SUB. DPTO. GESTION DEL RIESGO EN EMERGENCIAS, DESASTRES Y TELECOMUNICACIONES | P10: No Ejecutado
A11: 1057532-1-PC24 | B11: Arrastre | C11: Bienes y Servicios | D11: Sistema control de flota vehicular del Servicio de Salud Osorno | E11: Sistema de control de flota | F11: 1 | G11: Felipe Salvo Barriga | H11: 45292 | I11: Enc. Sección Mant. de Vehículos | J11: 36 | K11: 01-01-2024,01-02-2024,01-03-2024,01-04-2024,01-05-2024,01-06-2024,01-07-2024,01-08-2024,01-09-2024,01-10-2024,01-11-2024,01-12-2024,01-01-2025,01-02-2025,01-03-2025,01-04-2025,01-05-2025,01-06-2025,01-07-2025,01-08-2025,01-09-2025,01-10-2025,01-11-2025,01-12-2025,01-01-2026,01-02-2026,01-03-2026,01-04-2026,01-05-2026,01-06-2026,01-07-2026,01-08-2026,01-09-2026,01-10-2026,01-11-2026,01-12-2026 | L11: 6712008 | M11: SECCION DE MANTENIMIENTO DE VEHICULOS | N11: SUBDIRECCION ADMINISTRATIVA | O11: ABASTECIMIENTO Y OPERACIONES | P11: No Ejecutado
A12: 1057532-209-PC25 | B12: Arrastre | C12: Bienes y Servicios | D12: Convenio - ADQUISICION DE 3 CUPOS DE RESIDENCIA PROTEGIDA PARA EL SERVICIO DE SALUD OSORNO EN LA PROVINCIA DE CONCEPCIÓN | E12: Servicio Residencial | F12: 2 | G12: Angelo Palma | H12: 45658 | I12: Jefe (s) Subdepto. Gestión Clínica y Administrativa Red Temática de Salud Mental de Especialidad | J12: 24 | K12: 01-01-2025,01-02-2025,01-03-2025,01-04-2025,01-05-2025,01-06-2025,01-07-2025,01-08-2025,01-09-2025,01-10-2025,01-11-2025,01-12-2025,01-01-2026,01-02-2026,01-03-2026,01-04-2026,01-05-2026,01-06-2026,01-07-2026,01-08-2026,01-09-2026,01-10-2026,01-11-2026,01-12-2026 | L12: 48115128 | M12: DEPARTAMENTO DE SALUD MENTAL | N12: SUBDIRECCION DE GESTION ASISTENCIAL | O12: SALUD MENTAL | P12: No Ejecutado
A13: 1057532-210-PC25 | B13: Arrastre | C13: Bienes y Servicios | D13: Convenio - ADQUISICION DE 12 CUPOS DE RESIDENCIA PROTEGIDA PARA EL SERVICIO DE SALUD OSORNO EN LA CIUDAD DE OSORNO | E13: Servicio Residencial | F13: 2 | G13: Angelo Palma | H13: 45658 | I13: Jefe (s) Subdepto. Gestión Clínica y Administrativa Red Temática de Salud Mental de Especialidad | J13: 24 | K13: 01-01-2025,01-02-2025,01-03-2025,01-04-2025,01-05-2025,01-06-2025,01-07-2025,01-08-2025,01-09-2025,01-10-2025,01-11-2025,01-12-2025,01-01-2026,01-02-2026,01-03-2026,01-04-2026,01-05-2026,01-06-2026,01-07-2026,01-08-2026,01-09-2026,01-10-2026,01-11-2026,01-12-2026 | L13: 237155100 | M13: DEPARTAMENTO DE SALUD MENTAL | N13: SUBDIRECCION DE GESTION ASISTENCIAL | O13: SALUD MENTAL | P13: No Ejecutado
A14: 1057532-211-PC25 | B14: Arrastre | C14: Bienes y Servicios | D14: Convenio - ADQUISICION DE 10 CUPOS RESIDENCIA PROTEGIDA DE ALTA COMPLEJIDAD PARA EL SERVICIO DE SALUD OSORNO DE LA CIUDAD DE OSORNO | E14: Servicio Residencial | F14: 2 | G14: Angelo Palma | H14: 45658 | I14: Jefe (s) Subdepto. Gestión Clínica y Administrativa Red Temática de Salud Mental de Especialidad | J14: 24 | K14: 01-01-2025,01-02-2025,01-03-2025,01-04-2025,01-05-2025,01-06-2025,01-07-2025,01-08-2025,01-09-2025,01-10-2025,01-11-2025,01-12-2025,01-01-2026,01-02-2026,01-03-2026,01-04-2026,01-05-2026,01-06-2026,01-07-2026,01-08-2026,01-09-2026,01-10-2026,01-11-2026,01-12-2026 | L14: 284700000 | M14: DEPARTAMENTO DE SALUD MENTAL | N14: SUBDIRECCION DE GESTION ASISTENCIAL | O14: SALUD MENTAL | P14: No Ejecutado
A15: 1057532-281-PC26 | B15: PC26 | C15: Bienes y Servicios | D15: Mantención Plotter Canon IPF 770, del depto. de Proyectos. | E15: Mantencion | F15: 1 | G15: Mario Barrientos | H15: 46266 | I15: Jefe Subdepto. Diseño De Infraestructura De Salud | J15: 1 | K15: 46266 | L15: 1250000 | M15: DEPARTAMENTO DE PROYECTOS | N15: SUBDIRECCION ADMINISTRATIVA | O15: PROYECTOS | P15: No Ejecutado
A16: 1057532-282-PC26 | B16: PC26 | C16: Bienes y Servicios | D16: Compra rollos papel para impresión del Departamento de Proyectos SSO. | E16: Rollos | F16: 1 | G16: Mario Barrientos | H16: 46174 | I16: Jefe Subdepto. Diseño De Infraestructura De Salud | J16: 1 | K16: 46174 | L16: 300000 | M16: DEPARTAMENTO DE PROYECTOS | N16: SUBDIRECCION ADMINISTRATIVA | O16: PROYECTOS | P16: No Ejecutado
A17: 1057532-283-PC26 | B17: PC26 | C17: Bienes y Servicios | D17: Compra Tinta Plotter Canon IPF 770 | E17: Tinta Plotter | F17: 1 | G17: Mario Barrientos | H17: 46204 | I17: Jefe Subdepto. Diseño De Infraestructura De Salud | J17: 1 | K17: 46204 | L17: 1320000 | M17: DEPARTAMENTO DE PROYECTOS | N17: SUBDIRECCION ADMINISTRATIVA | O17: PROYECTOS | P17: No Ejecutado
A18: 1057532-284-PC26 | B18: PC26 | C18: Bienes y Servicios | D18: Adquisicición Hojas Prehospitalarias | E18: Talonarios | F18: 1 | G18: Silvia Delgado | H18: 46082 | I18: Encargada Proceso De Urgencia | J18: 1 | K18: 46082 | L18: 2000700 | M18: DEPARTAMENTO ARTICULACION DE LA RED ASISTENCIAL | N18: SUBDIRECCION DE GESTION ASISTENCIAL | O18: ARTICULACION DE LA RED ASISTENCIAL | P18: No Ejecutado
A19: 1057532-285-PC26 | B19: PC26 | C19: Bienes y Servicios | D19: Adquisicición Kit de Triage y Sistema de comando incidente | E19: Kit Sistema | F19: 1 | G19: Silvia Delgado | H19: 46082 | I19: Encargada Proceso De Urgencia | J19: 1 | K19: 46082 | L19: 1510005 | M19: DEPARTAMENTO ARTICULACION DE LA RED ASISTENCIAL | N19: SUBDIRECCION DE GESTION ASISTENCIAL | O19: ARTICULACION DE LA RED ASISTENCIAL | P19: No Ejecutado
A20: 1057532-286-PC26 | B20: PC26 | C20: Bienes y Servicios | D20: II Jornada de Capacitación Red de Urgencia | E20: Cafeteria | F20: 2 | G20: Silvia Delgado | H20: 46082 | I20: Encargada Proceso De Urgencia | J20: 1 | K20: 46082 | L20: 850000 | M20: DEPARTAMENTO ARTICULACION DE LA RED ASISTENCIAL | N20: SUBDIRECCION DE GESTION ASISTENCIAL | O20: ARTICULACION DE LA RED ASISTENCIAL | P20: No Ejecutado
A21: 1057532-286-PC26 | B21: PC26 | C21: Bienes y Servicios | D21: II Jornada de Capacitación Red de Urgencia | E21: Opalina | F21: 2 | G21: Silvia Delgado | H21: 46082 | I21: Encargada Proceso De Urgencia | J21: 1 | K21: 46082 | L21: 22500 | M21: DEPARTAMENTO ARTICULACION DE LA RED ASISTENCIAL | N21: SUBDIRECCION DE GESTION ASISTENCIAL | O21: ARTICULACION DE LA RED ASISTENCIAL | P21: No Ejecutado
A22: 1057532-287-PC26 | B22: PC26 | C22: Bienes y Servicios | D22: ?DIAGNÓSTICO Y DIALOGO PARTICIPATIVO COSAM RAHUE ?NOVIEMBRE 2026? | E22: Cafeteria | F22: 1 | G22: Camilo Martínez | H22: 46327 | I22: Director(S) | J22: 1 | K22: 46327 | L22: 540000 | M22: DEPARTAMENTO DE SALUD MENTAL | N22: SUBDIRECCION DE GESTION ASISTENCIAL | O22: SALUD MENTAL | P22: No Ejecutado
A23: 1057532-288-PC26 | B23: PC26 | C23: Bienes y Servicios | D23: Jornadas de encuentro y autocuidado Para usuarios y cuidadores ?SALUDABLE-MENTE en dispositivo COSAM RAHUE 2026 | E23: Alimentación | F23: 6 | G23: Camilo Martínez | H23: 46113 | I23: Director(S) | J23: 1 | K23: 46113 | L23: 135000 | M23: DEPARTAMENTO DE SALUD MENTAL | N23: SUBDIRECCION DE GESTION ASISTENCIAL | O23: SALUD MENTAL | P23: No Ejecutado
A24: 1057532-288-PC26 | B24: PC26 | C24: Bienes y Servicios | D24: Jornadas de encuentro y autocuidado Para usuarios y cuidadores ?SALUDABLE-MENTE en dispositivo COSAM RAHUE 2026 | E24: Alimentación | F24: 6 | G24: Camilo Martínez | H24: 46204 | I24: Director(S) | J24: 1 | K24: 46204 | L24: 135000 | M24: DEPARTAMENTO DE SALUD MENTAL | N24: SUBDIRECCION DE GESTION ASISTENCIAL | O24: SALUD MENTAL | P24: No Ejecutado
